<?xml version="1.0" ?>
<!-- =================================================================================== -->
<!-- |    This document was autogenerated by xacro from ar600.xacro                    | -->
<!-- |    EDITING THIS FILE BY HAND IS NOT RECOMMENDED                                 | -->
<!-- =================================================================================== -->
<robot name="ar600" xmlns:xacro="http://www.ros.org/wiki/xacro">
  <link name="base_link">
    <visual>
      <origin rpy="0 0 0" xyz="0 0 0"/>
      <geometry>
        <box size="0.05 0.05 0.05"/>
      </geometry>
      <material name="Cyan">
        <color rgba="0 1.0 1.0 1.0"/>
      </material>
    </visual>
    <inertial>
      <origin rpy="0 0 0" xyz="0 0.05 0"/>
      <mass value="5.045"/>
      <inertia ixx="0.0" ixy="0.0" ixz="0.0" iyy="0.0" iyz="0.0" izz="0.0"/>
    </inertial>
  </link>
  <link name="hip_fork_left">
    <visual>
      <origin rpy="0 0 0" xyz="0 0 0"/>
      <geometry>
        <box size="0.05 0.05 0.05"/>
      </geometry>
      <material name="Cyan">
        <color rgba="0 1.0 1.0 1.0"/>
      </material>
    </visual>
  </link>
  <link name="hip_cross_left">
    <visual>
      <origin rpy="0 0 0" xyz="0 0 0"/>
      <geometry>
        <box size="0.05 0.05 0.05"/>
      </geometry>
      <material name="Cyan">
        <color rgba="0 1.0 1.0 1.0"/>
      </material>
    </visual>
  </link>
  <link name="hip_left">
    <visual>
      <origin rpy="0 0 0" xyz="0 0 0"/>
      <geometry>
        <box size="0.05 0.05 0.05"/>
      </geometry>
      <material name="Cyan">
        <color rgba="0 1.0 1.0 1.0"/>
      </material>
    </visual>
  </link>
  <link name="shin_left">
    <visual>
      <origin rpy="0 0 0" xyz="0 0 0"/>
      <geometry>
        <box size="0.05 0.05 0.05"/>
      </geometry>
      <material name="Cyan">
        <color rgba="0 1.0 1.0 1.0"/>
      </material>
    </visual>
  </link>
  <link name="ankle_left">
    <visual>
      <origin rpy="0 0 0" xyz="0 0 0"/>
      <geometry>
        <box size="0.05 0.05 0.05"/>
      </geometry>
      <material name="Cyan">
        <color rgba="0 1.0 1.0 1.0"/>
      </material>
    </visual>
  </link>
  <link name="foot_left">
    <visual>
      <origin rpy="0 0 0" xyz="0 0 0"/>
      <geometry>
        <box size="0.05 0.05 0.05"/>
      </geometry>
      <material name="Cyan">
        <color rgba="0 1.0 1.0 1.0"/>
      </material>
    </visual>
  </link>
  <!-- hip z rotate (vertical)-->
  <joint name="hip_r_joint_left" type="revolute">
    <parent link="base_link"/>
    <child link="hip_fork_left"/>
    <!-- z unknown -->
    <origin rpy="0 0 0" xyz="0.088 0.0276 0"/>
    <axis xyz="0 0 1"/>
    <limit effort="10" lower="-0.349065850399" upper="0.349065850399" velocity="10"/>
  </joint>
  <!-- hip y rotate (side)-->
  <joint name="hip_s_joint_left" type="revolute">
    <parent link="hip_fork_left"/>
    <child link="hip_cross_left"/>
    <!-- unknown -->
    <origin rpy="0 0 0" xyz="0 0 -0.25"/>
    <axis xyz="0 1 0"/>
    <limit effort="10" lower="-0.191986217719" upper="0.349065850399" velocity="10"/>
  </joint>
  <!-- hip x rotate (forward)-->
  <joint name="hip_f_joint_left" type="revolute">
    <parent link="hip_cross_left"/>
    <child link="hip_left"/>
    <origin rpy="0 0 0" xyz="0 0 0"/>
    <axis xyz="1 0 0"/>
    <limit effort="10" lower="-0.785398163397" upper="1.2217304764" velocity="10"/>
  </joint>
  <!-- knee -->
  <joint name="knee_joint_left" type="revolute">
    <parent link="hip_left"/>
    <child link="shin_left"/>
    <origin rpy="0 0 0" xyz="0 0 -0.28"/>
    <axis xyz="1 0 0"/>
    <limit effort="10" lower="-2.44346095279" upper="0" velocity="10"/>
  </joint>
  <!-- ankle x (forward) -->
  <joint name="ankle_f_joint_left" type="revolute">
    <parent link="shin_left"/>
    <child link="ankle_left"/>
    <origin rpy="0 0 0" xyz="0 0 -0.28"/>
    <axis xyz="1 0 0"/>
    <limit effort="10" lower="-0.575958653158" upper="1.2217304764" velocity="10"/>
  </joint>
  <!-- ankle y (side) -->
  <joint name="ankle_s_joint_left" type="revolute">
    <parent link="ankle_left"/>
    <child link="foot_left"/>
    <origin rpy="0 0 0" xyz="0 0 0"/>
    <axis xyz="0 1 0"/>
    <limit effort="10" lower="-0.349065850399" upper="0.191986217719" velocity="10"/>
  </joint>
</robot>
