<?xml version="1.0"?>
<robot xmlns:xacro="http://www.ros.org/wiki/xacro">

	<!--
		Solid Works conversion
		x <- -x
		y <-  z
		z <-  y
	-->

	<xacro:macro name="head" params="parent"> 

		<link name="neck">
	 		<xacro:meshes file="neck"/>
	 		<inertial>
	 			<origin xyz="-0.02 0.00 0.02" rpy="0 0 0"/>
      			<mass value="0.633"/>
      			<inertia ixx="0.000884" ixy="0.000001" ixz="-0.000246"
      				                    iyy="0.000982" iyz="0.000500"
      				                                   izz="0.000627"/>
    		</inertial>
	 	</link>

	 	<link name="neck_fork">
	 		<xacro:meshes file="neck_fork"/>
	 		<inertial>
	 			<!-- z unknown -->
	 			<origin xyz="0.01 -0.01 -0.02" rpy="0 0 0"/>
      			<mass value="0.444"/>
      			<inertia ixx="0.000285" ixy="-0.000016" ixz="0.000073"
      				                    iyy="0.000401"  iyz="-0.000021"
      				                                    izz="0.000238"/>
    		</inertial>
	 	</link>

	 	<link name="neck_cross">
	 		<xacro:meshes file="neck_cross"/>
	 		<inertial>
	 			<origin xyz="0.01 0.01 0" rpy="0 0 0"/>
      			<mass value="0.320"/>
      			<inertia ixx="0.000054" ixy="-0.000002" ixz="0.000000"
      				                    iyy="0.000054"  iyz="0.000000"
      				                                    izz="0.000092"/>
    		</inertial>
	 	</link>

	 	<link name="head">
	 		<xacro:meshes file="head" collision="True"/>
	 		<inertial>
	 			<origin xyz="0.04 0.00 0.06" rpy="0 0 0"/>
      			<mass value="1.258"/>
      			<inertia ixx="0.005118" ixy="-0.000058" ixz="-0.000120"
      				                    iyy="0.005112"  iyz="-0.000172"
      				                                    izz="0.005643"/>
    		</inertial>
	 	</link>


	 	<!-- neck x (forward) -->
	 	<joint name="neck_f_joint"
	 		   type="revolute">
	 		<parent link="${parent}"/>
	 		<child link="neck"/>
	 		
	 		<!-- unknown -->
	 		<origin xyz="0 0.041 0.016" rpy="0 0 0"/>
	 		<axis xyz="-1 0 0"/>
	 		<limit lower="${0*d2r}" upper="${60*d2r}" effort="10" velocity="10"/>
	 	</joint>

	 	<!-- head z (rotate) -->
		<joint name="head_r_joint"
			   type="revolute">
			<parent link="neck"/>
	 		<child link="neck_fork"/>

	 		<!-- unknown -->
	 		<origin xyz="0 -0.034 0.13" rpy="0 0 0"/>
	 		<axis xyz="0 0 1"/>
	 		<limit lower="${-90*d2r}" upper="${90*d2r}" effort="10" velocity="10"/>
		</joint>

		<!-- head y (side) -->
		<joint name="head_s_joint"
			   type="revolute">
			<parent link="neck_fork"/>
	 		<child link="neck_cross"/>
	 		<origin xyz="0 0 0" rpy="0 0 0"/>
	 		<axis xyz="0 1 0"/>
	 		<limit lower="${-15*d2r}" upper="${15*d2r}" effort="10" velocity="10"/>
		</joint>

		<!-- head x (forward) -->
		<joint name="head_f_joint"
			   type="revolute">
			<parent link="neck_cross"/>
	 		<child link="head"/>
	 		<!-- z unknown -->
	 		<origin xyz="0 0 0" rpy="0 0 0"/>
	 		<axis xyz="1 0 0"/>
	 		<limit lower="${-20*d2r}" upper="${30*d2r}" effort="10" velocity="10"/>
		</joint>


		<xacro:transmission_block joint_name="neck_f_joint"/>
		<xacro:transmission_block joint_name="head_r_joint"/>
		<xacro:transmission_block joint_name="head_s_joint"/>
		<xacro:transmission_block joint_name="head_f_joint"/>

	 	

	</xacro:macro>
</robot>