<?xml version="1.0"?>
<robot xmlns:xacro="http://www.ros.org/wiki/xacro">

	<!--
		Solid Works conversion
		x <- z
		y <- x
		z <- y
	-->

	<xacro:macro name="leg" params="parent side"> 

		<xacro:left_right side="${side}"/>

		<!-- Links -->
		<link name="hip_fork_${side}">
	 		<xacro:meshes file="hip_fork_${side}" collision="True"/>
	 		<inertial>
	 			<origin xyz="${-0.02 * x_sign} 0 0.07" rpy="0 0 0"/>
      			<mass value="3.170"/>
      			<inertia ixx="0.009316" ixy="-0.000234" ixz="0.002895"
      				                    iyy="0.012979"  iyz="0.000000"
      				                                    izz="0.006561"/>
    		</inertial>
	 	</link>

	 	<link name="hip_cross_${side}">
	 		<xacro:meshes file="hip_cross_${side}"/>
	 		<inertial>
	 			<origin xyz="${-0.03 * x_sign} 0.01 0.00" rpy="0 0 0"/>
      			<mass value="1.799"/>
      			<inertia ixx="0.001498" ixy="0.000126" ixz="0.000001"
      				                    iyy="0.001990" iyz="-0.000016"
      				                                   izz="0.002404"/>
    		</inertial>
	 	</link>

	 	<link name="hip_${side}">
	 		<xacro:meshes file="hip_${side}" collision="True"/>
	 		<inertial>
	 			<origin xyz="${0.01 * x_sign} 0.00 -0.14" rpy="0 0 0"/>
      			<mass value="6.779"/>
      			<inertia ixx="0.037615" ixy="0.000139" ixz="-0.000896"
      				                    iyy="0.031299" iyz="-0.000182"
      				                                   izz="0.012270"/>
    		</inertial>
	 	</link>

	 	<link name="shin_${side}">
	 		<xacro:meshes file="shin_${side}" collision="True"/>
	 		<inertial>
	 			<origin xyz="0.00 0.01 -0.11" rpy="0 0 0"/>
      			<mass value="1"/>
      			<inertia ixx="0.028848" ixy="0.000053" ixz="-0.000056"
      				                    iyy="0.026849" iyz="0.001709"
      				                                   izz="0.005196"/>
    		</inertial>
	 	</link>

	 	<link name="ankle_${side}">
	 		<xacro:meshes file="ankle_${side}"/>
	 		<inertial>
	 			<origin xyz="${-0.02 * x_sign} 0.01 0.00" rpy="0 0 0"/>
      			<mass value="1"/>
      			<inertia ixx="0.000424" ixy="-0.000001" ixz="-0.000001"
      				                    iyy="0.000603"  iyz="0.000001"
      				                                    izz="0.000898"/>
    		</inertial>
	 	</link>

	 	<link name="foot_${side}">
	 		<xacro:meshes file="foot_${side}" collision="True"/>
	 		<inertial>
	 			<origin xyz="${0.03 * x_sign} 0.00 -0.06" rpy="0 0 0"/>
      			<mass value="1"/>
      			<inertia ixx="0.006101" ixy="-0.000307" ixz="-0.001261"
      				                    iyy="0.012336"  iyz="0.000060"
      				                                    izz="0.013546"/>
    		</inertial>
	 	</link>


	 	<!-- hip z rotate (vertical)-->
	 	<joint name="hip_r_joint_${side}"
	 		   type="revolute">
	 		<parent link="${parent}"/>
	 		<child link="hip_fork_${side}"/>	 		
	 		<origin xyz="${0.088 * x_sign} 0.0276 0" rpy="0 0 0"/>
	 		<axis xyz="0 0 ${-x_sign}"/>
	 		<limit lower="${-20*d2r}" upper="${20*d2r}" effort="10" velocity="10"/>
	 	</joint>

	 	<!-- hip y rotate (side)-->
	 	<joint name="hip_s_joint_${side}"
	 		   type="revolute">
	 		<parent link="hip_fork_${side}"/>
	 		<child link="hip_cross_${side}"/>	 		
	 		<origin xyz="0 0 0" rpy="0 0 0"/>
	 		<axis xyz="0 ${-x_sign} 0"/>	 		
	 		<xacro:lr_limit side="${side}" lower="${-11*d2r}" upper="${20*d2r}" effort="10" velocity="10"/>
	 	</joint>

	 	<!-- hip x rotate (forward)-->
	 	<joint name="hip_f_joint_${side}"
	 		   type="revolute">
	 		<parent link="hip_cross_${side}"/>
	 		<child link="hip_${side}"/>
	 		<origin xyz="0 0 0" rpy="0 0 0"/>
	 		<axis xyz="1 0 0"/>
	 		<limit lower="${-45*d2r}" upper="${70*d2r}" effort="10" velocity="10"/>-	 		
	 	</joint>

	 	<!-- knee -->
	 	<joint name="knee_joint_${side}"
	 		   type="revolute">
	 		<parent link="hip_${side}"/>
	 		<child link="shin_${side}"/>
	 		<origin xyz="0 0 -0.28" rpy="0 0 0"/>
	 		<axis xyz="1 0 0"/>
	 		<limit lower="${-140*d2r}" upper="0" effort="10" velocity="10"/>
	 	</joint>

	 	<!-- ankle x (forward) -->
	 	<joint name="ankle_f_joint_${side}"
	 		   type="revolute">
	 		<parent link="shin_${side}"/>
	 		<child link="ankle_${side}"/>
	 		<origin xyz="0 0 -0.28" rpy="0 0 0"/>
	 		<axis xyz="1 0 0"/>
	 		<limit lower="${-33*d2r}" upper="${70*d2r}" effort="10" velocity="10"/>
	 	</joint>

	 	<!-- ankle y (side) -->
	 	<joint name="ankle_s_joint_${side}"
	 		   type="revolute">
	 		<parent link="ankle_${side}"/>
	 		<child link="foot_${side}"/>
	 		<origin xyz="0 0 0" rpy="0 0 0"/>
	 		<axis xyz="0 ${-x_sign} 0"/>	 		
	 		<xacro:lr_limit side="${side}" lower="${-20*d2r}" upper="${11*d2r}" effort="10" velocity="10"/>
	 	</joint>

	 	<xacro:transmission_block joint_name="hip_r_joint_${side}"/>
	 	<xacro:transmission_block joint_name="hip_s_joint_${side}"/>
	 	<xacro:transmission_block joint_name="hip_f_joint_${side}"/>
	 	<xacro:transmission_block joint_name="knee_joint_${side}"/>
	 	<xacro:transmission_block joint_name="ankle_f_joint_${side}"/>
	 	<xacro:transmission_block joint_name="ankle_s_joint_${side}"/>

 	</xacro:macro>

</robot>
