<?xml version="1.0"?>
<robot xmlns:xacro="http://www.ros.org/wiki/xacro">

	<!--
		Solid Works conversion
		x <- -x
		y <-  z
		z <-  y
	-->

	<xacro:macro name="leg" params="parent side"> 

		<xacro:left_right side="${side}"/>

		<!-- Links -->
		<link name="hip_fork_${side}">
	 		<xacro:meshes file="hip_fork_${side}" collision="True"/>
	 		<inertial>
	 			<origin xyz="0 -0.02 0.07" rpy="0 0 0"/>
      			<mass value="3.170"/>
      			<inertia ixx="1.0" ixy="1.0" ixz="1.0"
      				     iyy="1.0" iyz="1.0"
      				     izz="1.0"/>
    		</inertial>
	 	</link>

	 	<link name="hip_cross_${side}">
	 		<xacro:meshes file="hip_cross_${side}"/>
	 		<inertial>
	 			<origin xyz="${-0.01 * x_sign} -0.03 0" rpy="0 0 0"/>
      			<mass value="1.799"/>
      			<inertia ixx="1.0" ixy="1.0" ixz="1.0"
      				     iyy="1.0" iyz="1.0"
      				     izz="1.0"/>
    		</inertial>
	 	</link>

	 	<link name="hip_${side}">
	 		<xacro:meshes file="hip_${side}" collision="True"/>
	 		<inertial>
	 			<origin xyz="0 0.01 -0.14" rpy="0 0 0"/>
      			<mass value="6.779"/>
      			<inertia ixx="1.0" ixy="1.0" ixz="1.0"
      				     iyy="1.0" iyz="1.0"
      				     izz="1.0"/>
    		</inertial>
	 	</link>

	 	<link name="shin_${side}">
	 		<xacro:meshes file="shin_${side}" collision="True"/>
	 		<inertial>
	 			<origin xyz="${0.01 * x_sign} 0 -0.11" rpy="0 0 0"/>
      			<mass value="1"/>
      			<inertia ixx="1.0" ixy="1.0" ixz="1.0"
      				     iyy="1.0" iyz="1.0"
      				     izz="1.0"/>
    		</inertial>
	 	</link>

	 	<link name="ankle_${side}">
	 		<xacro:meshes file="ankle_${side}"/>
	 		<inertial>
	 			<origin xyz="${-0.01 * x_sign} -0.02 0" rpy="0 0 0"/>
      			<mass value="1"/>
      			<inertia ixx="1.0" ixy="1.0" ixz="1.0"
      				     iyy="1.0" iyz="1.0"
      				     izz="1.0"/>
    		</inertial>
	 	</link>

	 	<link name="foot_${side}">
	 		<xacro:meshes file="foot_${side}" collision="True"/>
	 		<inertial>
	 			<origin xyz="0 0.03 -0.06" rpy="0 0 0"/>
      			<mass value="1"/>
      			<inertia ixx="1.0" ixy="1.0" ixz="1.0"
      				     iyy="1.0" iyz="1.0"
      				     izz="1.0"/>
    		</inertial>
	 	</link>


	 	<!-- hip z rotate (vertical)-->
	 	<joint name="hip_r_joint_${side}"
	 		   type="revolute">
	 		<parent link="${parent}"/>
	 		<child link="hip_fork_${side}"/>	 		
	 		<origin xyz="${0.088 * x_sign} 0.0276 0" rpy="0 0 0"/>
	 		<axis xyz="0 0 1"/>
	 		<limit lower="${-20*d2r}" upper="${20*d2r}" effort="10" velocity="10"/>
	 	</joint>

	 	<!-- hip y rotate (side)-->
	 	<joint name="hip_s_joint_${side}"
	 		   type="revolute">
	 		<parent link="hip_fork_${side}"/>
	 		<child link="hip_cross_${side}"/>	 		
	 		<origin xyz="0 0 0" rpy="0 0 0"/>
	 		<axis xyz="0 1 0"/>	 		
	 		<xacro:lr_limit side="${side}" lower="${-11*d2r}" upper="${20*d2r}" effort="10" velocity="10"/>
	 	</joint>

	 	<!-- hip x rotate (forward)-->
	 	<joint name="hip_f_joint_${side}"
	 		   type="revolute">
	 		<parent link="hip_cross_${side}"/>
	 		<child link="hip_${side}"/>
	 		<origin xyz="0 0 0" rpy="0 0 0"/>
	 		<axis xyz="1 0 0"/>
	 		<limit lower="${-45*d2r}" upper="${70*d2r}" effort="10" velocity="10"/>-	 		
	 	</joint>

	 	<!-- knee -->
	 	<joint name="knee_joint_${side}"
	 		   type="revolute">
	 		<parent link="hip_${side}"/>
	 		<child link="shin_${side}"/>
	 		<origin xyz="0 0 -0.28" rpy="0 0 0"/>
	 		<axis xyz="1 0 0"/>
	 		<limit lower="${-140*d2r}" upper="0" effort="10" velocity="10"/>
	 	</joint>

	 	<!-- ankle x (forward) -->
	 	<joint name="ankle_f_joint_${side}"
	 		   type="revolute">
	 		<parent link="shin_${side}"/>
	 		<child link="ankle_${side}"/>
	 		<origin xyz="0 0 -0.28" rpy="0 0 0"/>
	 		<axis xyz="1 0 0"/>
	 		<limit lower="${-33*d2r}" upper="${70*d2r}" effort="10" velocity="10"/>
	 	</joint>

	 	<!-- ankle y (side) -->
	 	<joint name="ankle_s_joint_${side}"
	 		   type="revolute">
	 		<parent link="ankle_${side}"/>
	 		<child link="foot_${side}"/>
	 		<origin xyz="0 0 0" rpy="0 0 0"/>
	 		<axis xyz="0 1 0"/>	 		
	 		<xacro:lr_limit side="${side}" lower="${-20*d2r}" upper="${11*d2r}" effort="10" velocity="10"/>
	 	</joint>

 	</xacro:macro>

</robot>